package com.kodilla.exception.test;

public class FirstChallenge {

    public double divide(double a, double b) throws ArithmeticException {
        if (b == 0) {
            throw new ArithmeticException("Division by zero is not allowed!");
        }
        return a / b;
    }

    /**
     * This main can throw an ArithmeticException!!!
     */
    public static void main(String[] args) {
        FirstChallenge firstChallenge = new FirstChallenge();

        try {
            double result = firstChallenge.divide(3, 0);
            System.out.println("Result: " + result);
        } catch (ArithmeticException e) {
            System.out.println("Exception caught: " + e.getMessage());
        } finally {
            System.out.println("This block is always executed - finally.");
        }

        System.out.println("Program continues after exception handling.");
    }
}
